
import os
from datetime import datetime, timedelta
from jose import jwt, JWTError
from fastapi import Depends, HTTPException, status
from fastapi.security import OAuth2PasswordBearer
from passlib.context import CryptContext
from sqlalchemy.orm import Session
from .database import SessionLocal
from . import models

SECRET_KEY = os.getenv("SECRET_KEY", "dev-secret")
ACCESS_TOKEN_EXPIRE_MINUTES = int(os.getenv("ACCESS_TOKEN_EXPIRE_MINUTES", "43200")) # 30 jours
ALGORITHM = "HS256"

pwd_context = CryptContext(schemes=["bcrypt"], deprecated="auto")
oauth2_scheme = OAuth2PasswordBearer(tokenUrl="/auth/login")

def get_db():
    db = SessionLocal()
    try:
        yield db
    finally:
        db.close()

def verify_password(plain_password, hashed_password):
    return pwd_context.verify(plain_password, hashed_password)

def get_password_hash(password):
    return pwd_context.hash(password)

def create_access_token(data: dict, expires_delta: timedelta | None = None):
    to_encode = data.copy()
    expire = datetime.utcnow() + (expires_delta or timedelta(minutes=ACCESS_TOKEN_EXPIRE_MINUTES))
    to_encode.update({"exp": expire})
    return jwt.encode(to_encode, SECRET_KEY, algorithm=ALGORITHM)

def get_current_user(token: str = Depends(oauth2_scheme), db: Session = Depends(get_db)) -> models.User:
    credentials_exception = HTTPException(
        status_code=status.HTTP_401_UNAUTHORIZED,
        detail="Impossible de valider les identifiants",
        headers={"WWW-Authenticate": "Bearer"},
    )
    try:
        payload = jwt.decode(token, SECRET_KEY, algorithms=[ALGORITHM])
        user_id: int | None = payload.get("sub")
        if user_id is None:
            raise credentials_exception
    except JWTError:
        raise credentials_exception
    user = db.get(models.User, int(user_id))
    if user is None:
        raise credentials_exception
    return user
